Traceback (most recent call last):
  File "/home/fart/TeamFabulous/comms/main_program.py", line 34, in <module>
    socket.bind('tcp://*:5550')
  File "zmq/backend/cython/socket.pyx", line 487, in zmq.backend.cython.socket.Socket.bind (zmq/backend/cython/socket.c:5156)
  File "zmq/backend/cython/checkrc.pxd", line 25, in zmq.backend.cython.checkrc._check_rc (zmq/backend/cython/socket.c:7535)
    raise ZMQError(errno)
ZMQError: Address already in use
